Workbook

Sheet Overall
B1: Bilateral FTAs | C1: 2024 GDP (USD bn) | D1: % of ASEAN GDP | E1: Trade as GDP (%) | F1: Trade in Goods balance(USD bn) | G1: Share of intra-ASEAN trade in goods | H1: Internal (python) | I1: Internal (Wcopyfind) | J1: External (python) | K1: External (Wcopyfind) | L1: Retention rate
A2: Brunei | B2: 1 | C2: 15.34 | D2: =C2/SUM(C2:C12) -> 0.0038498411 | E2: 1.33 | F2: 5 | G2: 1 | J2: ='ASEAN (python)'!$B$1 -> 12.67 | K2: ='ASEAN (Wcopyfind)'!$B$1 -> 0.12
A3: Cambodia | B3: 4 | C3: 46.35 | D3: =C3/SUM(C2:C12) -> 0.011632343 | E3: 1.43 | F3: -2.02 | G3: 1.9 | H3: ='Internal (python)'!$B$1 -> 12.326667 | I3: ='Internal (Wcopyfind)'!$B$1 -> 0.165 | J3: ='ASEAN (python)'!$D$1 -> 8.655 | K3: ='ASEAN (Wcopyfind)'!$D$1 -> 0.0775 | L3: =J3/H3 -> 0.70213629
A4: Indonesia | B4: 7 | C4: 1396.3 | D4: =C4/SUM(C2:C12) -> 0.35042589 | E4: 0.43 | F4: 31.33 | G4: 12.9 | H4: ='Internal (python)'!$D$1 -> 18.24619 | I4: ='Internal (Wcopyfind)'!$D$1 -> 0.17380952 | J4: ='ASEAN (python)'!$F$1 -> 14.654286 | K4: ='ASEAN (Wcopyfind)'!$F$1 -> 0.13714286 | L4: =J4/H4 -> 0.80314221
A5: Laos | B5: 1 | C5: 16.5 | D5: =C5/SUM(C2:C12) -> 0.0041409634 | E5: 0.75 | F5: 1.53 | G5: 1.3 | J5: ='ASEAN (python)'!$H$1 -> 2.49 | K5: ='ASEAN (Wcopyfind)'!$H$1 -> 0.02
A6: Malaysia | B6: 9 | C6: 422.23 | D6: =C6/SUM(C2:C12) -> 0.105966 | E6: 1.37 | F6: 30.05 | G6: 20.3 | H6: ='Internal (python)'!$F$1 -> 22.640278 | I6: ='Internal (Wcopyfind)'!$F$1 -> 0.21527778 | J6: ='ASEAN (python)'!$J$1 -> 15.821111 | K6: ='ASEAN (Wcopyfind)'!$J$1 -> 0.14777778 | L6: =J6/H6 -> 0.69880375
A7: Myanmar | B7: 0 | C7: 74.07 | D7: =C7/SUM(C2:C12) -> 0.018589161 | F7: 2.47 | G7: 1.3
A8: Philippines | B8: 3 | C8: 461.62 | D8: =C8/SUM(C2:C12) -> 0.11585161 | E8: 0.66 | F8: -71.59 | G8: 6.8 | H8: ='Internal (python)'!$H$1 -> 10.176667 | I8: ='Internal (Wcopyfind)'!$H$1 -> 0.093333333 | J8: ='ASEAN (python)'!$L$1 -> 8.72 | K8: ='ASEAN (Wcopyfind)'!$L$1 -> 0.08 | L8: =J8/H8 -> 0.8568621
A9: Singapore | B9: 19 | C9: 547.39 | D9: =C9/SUM(C2:C12) -> 0.13737709 | E9: 3.22 | F9: 46.9 | G9: 29.2 | H9: ='Internal (python)'!$J$1 -> 21.255132 | I9: ='Internal (Wcopyfind)'!$J$1 -> 0.2035 | J9: ='ASEAN (python)'!$N$1 -> 13.2955 | K9: ='ASEAN (Wcopyfind)'!$N$1 -> 0.123 | L9: =J9/H9 -> 0.62551953
A10: Thailand | B10: 7 | C10: 526.52 | D10: =C10/SUM(C2:C12) -> 0.1321394 | E10: 1.37 | F10: -6.28 | G10: 15.1 | H10: ='Internal (python)'!$L$1 -> 12.736053 | I10: ='Internal (Wcopyfind)'!$L$1 -> 0.12394737 | J10: ='ASEAN (python)'!$P$1 -> 8.3671429 | K10: ='ASEAN (Wcopyfind)'!$P$1 -> 0.075714286 | L10: =J10/H10 -> 0.65696516
A11: Timor-Leste | B11: 0 | C11: 1.87 | D11: =C11/SUM(C2:C12) -> 0.00046930919 | E11: 0.95
A12: Vietnam | B12: 8 | C12: 476.39 | D12: =C12/SUM(C2:C12) -> 0.1195584 | E12: 1.74 | F12: 24.11 | G12: 10.1 | H12: ='Internal (python)'!$N$1 -> 15.5125 | I12: ='Internal (Wcopyfind)'!$N$1 -> 0.14571429 | J12: ='ASEAN (python)'!$R$1 -> 12.005 | K12: ='ASEAN (Wcopyfind)'!$R$1 -> 0.11125 | L12: =J12/H12 -> 0.77389202
A14: Average | H14: =SUM(H2:H12)/COUNT(H2:H12) -> 16.127641 | I14: =SUM(I2:I12)/COUNT(I2:I12) -> 0.16008318 | J14: =SUM(J2:J12)/COUNT(J2:J12) -> 10.742004 | K14: =SUM(K2:K12)/COUNT(K2:K12) -> 0.09915388 | L14: =SUM(L2:L12)/COUNT(L2:L12) -> 0.73104587

Sheet Internal (python)
A1: Cambodia | B1: =SUM(A2:B7)/COUNT(A2:B7) -> 12.326667 | C1: Indonesia | D1: =SUM(C2:D22)/COUNT(C2:D22) -> 18.24619 | E1: Malaysia | F1: =SUM(E2:F37)/COUNT(E2:F37) -> 22.640278 | G1: Philippines | H1: =SUM(G2:H4)/COUNT(G2:H4) -> 10.176667 | I1: Singapore | J1: =SUM(I2:J191)/COUNT(I2:J191) -> 21.255132 | K1: Thailand | L1: =SUM(K2:L20)/COUNT(K2:L20) -> 12.736053 | M1: Vietnam | N1: =SUM(M2:N29)/COUNT(M2:N29) -> 15.5125
A2: 21.31 | B2: 20.79 | C2: 36.27 | D2: 17.03 | E2: 31.94 | F2: 41.56 | G2: 5.74 | H2: 11.14 | I2: 27.08 | J2: 14.71 | K2: 0.84 | L2: 16.03 | M2: 16.8 | N2: 22.16
A3: 29.79 | B3: 16.71 | C3: 12.16 | D3: 31.88 | E3: 21.27 | F3: 14.31 | G3: 10.14 | H3: 13.07 | I3: 32.25 | J3: 10.5 | K3: 60.95 | L3: 55.18 | M3: 19.47 | N3: 12.15
A4: 0.4 | B4: 3.17 | C4: 5.56 | D4: 16.14 | E4: 12.93 | F4: 22.41 | G4: 12.6 | H4: 8.37 | I4: 29.31 | J4: 12.75 | K4: 25.24 | L4: 20.72 | M4: 17.73 | N4: 3.94
A5: 29.57 | B5: 16.99 | C5: 10.61 | D5: 19.84 | E5: 13.45 | F5: 12.1 | I5: 14.8 | J5: 15.23 | K5: 10.94 | L5: 10.96 | M5: 15.21 | N5: 10.59
A6: 0.4 | B6: 3.2 | C6: 21.75 | D6: 34.74 | E6: 23.51 | F6: 20.28 | I6: 26.41 | J6: 8.2 | K6: 0.91 | L6: 9.67 | M6: 29.05 | N6: 15.32
A7: 0.37 | B7: 5.22 | C7: 20.25 | D7: 24.09 | E7: 19.54 | F7: 17.53 | I7: 22.18 | J7: 16.49 | K7: 16.23 | L7: 12.67 | M7: 23.18 | N7: 13.54
C8: 4.38 | D8: 24.45 | E8: 22.71 | F8: 16.11 | I8: 22.29 | J8: 7.31 | K8: 13.25 | L8: 0.63 | M8: 10.28 | N8: 11.2
C9: 2.92 | D9: 18.04 | E9: 17.83 | F9: 12.66 | I9: 17.36 | J9: 5.58 | K9: 8.5 | L9: 0.37 | M9: 19.31 | N9: 9.13
C10: 4.95 | D10: 19.73 | E10: 28.8 | F10: 14.9 | I10: 15.75 | J10: 3.21 | K10: 7.52 | L10: 0.4 | M10: 21.81 | N10: 3.67
C11: 8.29 | D11: 28.2 | E11: 20.01 | F11: 26.65 | I11: 21.82 | J11: 6.94 | K11: 8.5 | L11: 4.72 | M11: 26.04 | N11: 13.74
C12: 13.39 | D12: 33.91 | E12: 19.06 | F12: 13.18 | I12: 27.11 | J12: 10.65 | K12: 5.89 | L12: 0.24 | M12: 37.81 | N12: 15.12
C13: 7.16 | D13: 7.93 | E13: 39.13 | F13: 25.94 | I13: 25.91 | J13: 3.53 | K13: 24.3 | L13: 22.03 | M13: 23.78 | N13: 10.53
C14: 19.75 | D14: 14.08 | E14: 30.84 | F14: 21.26 | I14: 17.27 | J14: 11.48 | K14: 10.98 | L14: 12.16 | M14: 3.69 | N14: 3.05
C15: 26.85 | D15: 16.36 | E15: 32.6 | F15: 17.78 | I15: 22.54 | J15: 6.68 | K15: 0.69 | L15: 8.08 | M15: 18.17 | N15: 6.46
C16: 31.46 | D16: 14.27 | E16: 22.52 | F16: 12.29 | I16: 21.62 | J16: 7.27 | K16: 17.61 | L16: 15.18 | M16: 14.66 | N16: 16.36
C17: 17.44 | D17: 11.23 | E17: 12.39 | F17: 31.89 | I17: 21.16 | J17: 14.56 | K17: 12.25 | L17: 14.96 | M17: 18.64 | N17: 15.76
C18: 22.41 | D18: 12.33 | E18: 12.61 | F18: 16.86 | I18: 26.12 | J18: 4.96 | K18: 0.46 | L18: 5.99 | M18: 15.41 | N18: 14.43
C19: 22.65 | D19: 9.28 | E19: 23.79 | F19: 30.5 | I19: 17.57 | J19: 2.81 | K19: 21.71 | L19: 20.65 | M19: 6.15 | N19: 10.75
... C22: 29.76 | D22: 22.16 | E22: 20.33 | F22: 21.46 | I22: 27.28 | J22: 21.84 | K22: 5.13 | L22: 0.38 | M22: 8 | N22: 21.05
E23: 13.52 | F23: 7.02 | I23: 14.56 | J23: 27.58 | M23: 3.07 | N23: 15.08
E24: 36.79 | F24: 18.32 | I24: 28.53 | J24: 16.3 | M24: 27.58 | N24: 20.9
E25: 35.6 | F25: 18.43 | I25: 13.94 | J25: 19.07 | M25: 22.55 | N25: 18.92
E26: 45.58 | F26: 18.67 | I26: 40.15 | J26: 24.25 | M26: 5.6 | N26: 8.77
E27: 26.9 | F27: 11.02 | I27: 26.88 | J27: 15.89 | M27: 25.71 | N27: 28.47
E28: 17.51 | F28: 16.79 | I28: 22.67 | J28: 8.5 | M28: 9.87 | N28: 20.4
E29: 14.77 | F29: 14.73 | I29: 31.83 | J29: 18.64 | M29: 9.09 | N29: 16.96
E30: 20.27 | F30: 15.99 | I30: 27.72 | J30: 20.05
E31: 18.36 | F31: 14.49 | I31: 26.16 | J31: 6.55
E32: 38.44 | F32: 39.96 | I32: 10.17 | J32: 12.45
E33: 33.81 | F33: 27.81 | I33: 23.24 | J33: 12.68
E34: 22.39 | F34: 18.43 | I34: 30.03 | J34: 18.58
E35: 36.89 | F35: 29.18 | I35: 12.76 | J35: 16.15
E36: 22.29 | F36: 17.64 | I36: 25.8 | J36: 9.01
E37: 23.29 | F37: 23.31 | I37: 23.16 | J37: 6.82
I38: 21.7 | J38: 17.45
I39: 25.29 | J39: 33.78
I40: 11.46 | J40: 36.21
I41: 32.16 | J41: 30.65
I42: 16.2 | J42: 36.97
...

Sheet Internal (Wcopyfind)
A1: Cambodia | B1: =SUM(A2:B5)/COUNT(A2:B5) -> 0.165 | C1: Indonesia | D1: =SUM(C2:D22)/COUNT(C2:D22) -> 0.17380952 | E1: Malaysia | F1: =SUM(E2:F37)/COUNT(E2:F37) -> 0.21527778 | G1: Philippines | H1: =SUM(G2:H4)/COUNT(G2:H4) -> 0.093333333 | I1: Singapore | J1: =SUM(I2:J191)/COUNT(I2:J191) -> 0.2035 | K1: Thailand | L1: =SUM(K2:L20)/COUNT(K2:L20) -> 0.12394737 | M1: Vietnam | N1: =SUM(M2:N29)/COUNT(M2:N29) -> 0.14571429
A2: 0.2 | B2: 0.2 | C2: 0.16 | D2: 0.35 | E2: 0.4 | F2: 0.31 | G2: 0.1 | H2: 0.05 | I2: 0.14 | J2: 0.26 | K2: 0.16 | L2: 0 | M2: 0.21 | N2: 0.16
A3: 0.16 | B3: 0.28 | C3: 0.31 | D3: 0.11 | E3: 0.13 | F3: 0.2 | G3: 0.12 | H3: 0.09 | I3: 0.1 | J3: 0.31 | K3: 0.54 | L3: 0.6 | M3: 0.11 | N3: 0.18
A4: 0.16 | B4: 0.28 | C4: 0.23 | D4: 0.04 | E4: 0.14 | F4: 0.28 | G4: 0.08 | H4: 0.12 | I4: 0.2 | J4: 0.34 | K4: 0 | L4: 0.12 | M4: 0.08 | N4: 0.18
A5: 0.04 | B5: 0 | C5: 0.15 | D5: 0.05 | E5: 0.21 | F5: 0.12 | I5: 0.12 | J5: 0.29 | K5: 0.2 | L5: 0.24 | M5: 0.03 | N5: 0.17
C6: 0.17 | D6: 0.02 | E6: 0.26 | F6: 0.19 | I6: 0.21 | J6: 0.27 | K6: 0 | L6: 0.08 | M6: 0.03 | N6: 0.21
C7: 0.07 | D7: 0.06 | E7: 0.31 | F7: 0.12 | I7: 0.33 | J7: 0.24 | K7: 0.21 | L7: 0.23 | M7: 0.06 | N7: 0.17
C8: 0.19 | D8: 0.1 | E8: 0.11 | F8: 0.12 | I8: 0.14 | J8: 0.14 | K8: 0.1 | L8: 0.1 | M8: 0.1 | N8: 0.14
C9: 0.19 | D9: 0.04 | E9: 0.12 | F9: 0.18 | I9: 0.27 | J9: 0.14 | K9: 0.11 | L9: 0.1 | M9: 0.13 | N9: 0.25
C10: 0.13 | D10: 0.19 | E10: 0.16 | F10: 0.12 | I10: 0.36 | J10: 0.11 | K10: 0.14 | L10: 0.11 | M10: 0.15 | N10: 0.14
C11: 0.11 | D11: 0.17 | E11: 0.06 | F11: 0.12 | I11: 0.26 | J11: 0.11 | K11: 0.09 | L11: 0 | M11: 0.22 | N11: 0.07
C12: 0.34 | D12: 0.21 | E12: 0.19 | F12: 0.22 | I12: 0.08 | J12: 0.26 | K12: 0.04 | L12: 0.08 | M12: 0.15 | N12: 0.28
C13: 0.27 | D13: 0.08 | E13: 0.25 | F13: 0.38 | I13: 0.16 | J13: 0.28 | K13: 0.08 | L13: 0 | M13: 0.14 | N13: 0.36
C14: 0.16 | D14: 0.26 | E14: 0.29 | F14: 0.23 | I14: 0.3 | J14: 0.31 | K14: 0.06 | L14: 0 | M14: 0.15 | N14: 0.18
C15: 0.12 | D15: 0.21 | E15: 0.17 | F15: 0.35 | I15: 0.19 | J15: 0.27 | K15: 0.05 | L15: 0 | M15: 0.21 | N15: 0.08
C16: 0.18 | D16: 0.22 | E16: 0.16 | F16: 0.16 | I16: 0.1 | J16: 0.34 | K16: 0.12 | L16: 0.15 | M16: 0.2 | N16: 0.27
C17: 0.23 | D17: 0.19 | E17: 0.17 | F17: 0.19 | I17: 0.16 | J17: 0.21 | K17: 0.14 | L17: 0.16 | M17: 0.13 | N17: 0.22
... C20: 0.09 | D20: 0.22 | E20: 0.17 | F20: 0.34 | I20: 0.2 | J20: 0.11 | K20: 0 | L20: 0.04 | M20: 0.2 | N20: 0.07
C21: 0.11 | D21: 0.18 | E21: 0.14 | F21: 0.14 | I21: 0.1 | J21: 0.14 | M21: 0.18 | N21: 0.22
C22: 0.21 | D22: 0.29 | E22: 0.39 | F22: 0.37 | I22: 0.22 | J22: 0.09 | M22: 0.27 | N22: 0.25
E23: 0.15 | F23: 0.21 | I23: 0.07 | J23: 0.22 | M23: 0.11 | N23: 0.1
E24: 0.17 | F24: 0.32 | I24: 0.24 | J24: 0.39 | M24: 0.02 | N24: 0.03
E25: 0.24 | F25: 0.22 | I25: 0.25 | J25: 0.25 | M25: 0.1 | N25: 0.05
E26: 0.18 | F26: 0.44 | I26: 0.15 | J26: 0.19 | M26: 0.14 | N26: 0.02
E27: 0.15 | F27: 0.19 | I27: 0.09 | J27: 0.29 | M27: 0.08 | N27: 0.05
E28: 0.27 | F28: 0.32 | I28: 0.37 | J28: 0.35 | M28: 0.19 | N28: 0.09
E29: 0.28 | F29: 0.36 | I29: 0.08 | J29: 0.19 | M29: 0.16 | N29: 0.08
E30: 0.12 | F30: 0.17 | I30: 0.05 | J30: 0.17
E31: 0.12 | F31: 0.22 | I31: 0.15 | J31: 0.26
E32: 0.2 | F32: 0.19 | I32: 0.16 | J32: 0.16
E33: 0.1 | F33: 0.25 | I33: 0.1 | J33: 0.13
E34: 0.14 | F34: 0.17 | I34: 0.07 | J34: 0.25
E35: 0.17 | F35: 0.21 | I35: 0.27 | J35: 0.26
E36: 0.17 | F36: 0.21 | I36: 0.06 | J36: 0.14
E37: 0.22 | F37: 0.22 | I37: 0.41 | J37: 0.42
I38: 0.03 | J38: 0.15
I39: 0.08 | J39: 0.22
I40: 0.11 | J40: 0.19
I41: 0.06 | J41: 0.14
I42: 0.06 | J42: 0.31
...

Sheet ASEAN (python)
A1: Brunei | B1: =SUM(B2:B2)/COUNT(B2:B2) -> 12.67 | C1: Cambodia | D1: =SUM(D2:D5)/COUNT(D2:D5) -> 8.655 | E1: Indonesia | F1: =SUM(F2:F8)/COUNT(F2:F8) -> 14.654286 | G1: Laos | H1: =SUM(H2:H2)/COUNT(H2:H2) -> 2.49 | I1: Malaysia | J1: =SUM(J2:J10)/COUNT(J2:J10) -> 15.821111 | K1: Philippines | L1: =SUM(L2:L4)/COUNT(L2:L4) -> 8.72 | M1: Singapore | N1: =SUM(N2:N21)/COUNT(N2:N21) -> 13.2955 | O1: Thailand | P1: =SUM(P2:P8)/COUNT(P2:P8) -> 8.3671429 | Q1: Vietnam | R1: =SUM(R2:R9)/COUNT(R2:R9) -> 12.005
A2: 146_Brunei Japan_2007Cut.txt | B2: 12.67 | C2: CA-China (2020).txt | D2: 13.13 | E2: ID-Aus (2019).txt | F2: 25.05 | G2: LA-US (2003).txt | H2: 2.49 | I2: 517_Japan Malaysia_2005Cut.txt | J2: 13.25 | K2: 519_Japan Philippines_2006Cut.txt | L2: 12.79 | M2: 396_EFTA Singapore_2002Cut.txt | N2: 9.01 | O2: 632_New Zealand Thailand_2005Cut.txt | P2: 11.63 | Q2: 523_Japan Vietnam_2008Cut.txt | R2: 11.83
C3: CA-ROK (2021).txt | D3: 8.3 | E3: ID-Canada (2025).txt | F3: 14.81 | I3: 599_Malaysia Pakistan_2007Cut.txt | J3: 14.67 | K3: PH-EFTA (2016).txt | L3: 4.48 | M3: 475_Gulf Cooperation Council (GCC) Singapore_2008Cut.txt | N3: 12.1 | O3: 771_Peru Thailand_2005Cut.txt | P3: 0.19 | Q3: VN-Chile (2011).txt | R3: 8.6
C4: CA-UAE (2023).txt | D4: 12.99 | E4: ID-Chile (2017).txt | F4: 6.86 | I4: 795_Australia Malaysia_2012 cut.txt | J4: 19.69 | K4: PH-Korea (2023).txt | L4: 8.89 | M4: 493_India Singapore_2005Cut.txt | N4: 17.33 | O4: 83_Australia Thailand_2004.txt | P4: 9.79 | Q4: VN-EEU (2015).txt | R4: 11.17
C5: CA-US (2025).txt | D5: 0.2 | E5: ID-EFTA (2018).txt | F5: 9.53 | I5: 800_Chile Malaysia_2010 cut.txt | J5: 6.02 | M5: 520_Japan Singapore_2002Cut.txt | N5: 14.83 | O5: TH-Chile (2013).txt | P5: 12.07 | Q5: VN-EU + Investment (2019).txt | R5: 12.77
E6: ID-Japan (2007).txt | F6: 11.15 | I6: MY-EFTA (2025).txt | J6: 11.68 | M6: 534_Jordan Singapore_2004Cut.txt | N6: 6.48 | O6: TH-EFTA (2025).txt | P6: 11.41 | Q6: VN-Israel (2023).txt | R6: 11.94
E7: ID-ROK (2020).txt | F7: 21.35 | I7: MY-India (2011).txt | J7: 20.62 | M7: 550_Korea Singapore_2005Cut.txt | N7: 13.86 | O7: TH-India (2003).txt | P7: 0.68 | Q7: VN-ROK (2015).txt | R7: 19.7
E8: ID-UAE (2022).txt | F8: 13.83 | I8: MY-NZ (2009).txt | J8: 19.68 | M8: 631_New Zealand Singapore_2000Cut.txt | N8: 6.79 | O8: TH-Japan (2007).txt | P8: 12.8 | Q8: VN-UAE (2024).txt | R8: 12.04
I9: MY-Turkey (2022).txt | J9: 23.69 | M9: 641_Panama Singapore_2006Cut.txt | N9: 13.3 | Q9: VN-US (2000).txt | R9: 7.99
I10: MY-UAE (2025).txt | J10: 13.09 | M10: 644_Peru Singapore_2008Cut.txt | N10: 14.04
M11: 658_Singapore US_2003Cut.txt | N11: 13.08
M12: 814_Costa Rica Singapore_2010 cut.txt | N12: 14.12
M13: 82_Australia Singapore_2003Cut.txt | N13: 15.81
M14: 874_EC Singapore_ (cut) + Investment (2018).txt | N14: 14.34
M15: SG-Armenia (2019).txt | N15: 11.88
M16: SG-China (2023).txt | N16: 20.59
M17: SG-Costa Rica (2010).txt | N17: 14.14
M18: SG-Kazakh (2023).txt | N18: 11.57
M19: SG-Mercosur (2023).txt | N19: 13.61
M20: SG-Pacific Alliance (2022).txt | N20: 15.39
M21: SG-TW (2013).txt | N21: 13.64

Sheet ASEAN (Wcopyfind)
A1: Brunei | B1: =SUM(B2:B2)/COUNT(B2:B2) -> 0.12 | C1: Cambodia | D1: =SUM(D2:D5)/COUNT(D2:D5) -> 0.0775 | E1: Indonesia | F1: =SUM(F2:F8)/COUNT(F2:F8) -> 0.13714286 | G1: Laos | H1: =SUM(H2:H2)/COUNT(H2:H2) -> 0.02 | I1: Malaysia | J1: =SUM(J2:J10)/COUNT(J2:J10) -> 0.14777778 | K1: Philippines | L1: =SUM(L2:L4)/COUNT(L2:L4) -> 0.08 | M1: Singapore | N1: =SUM(N2:N21)/COUNT(N2:N21) -> 0.123 | O1: Thailand | P1: =SUM(P2:P8)/COUNT(P2:P8) -> 0.075714286 | Q1: Vietnam | R1: =SUM(R2:R9)/COUNT(R2:R9) -> 0.11125
A2: 146_Brunei Japan_2007Cut.txt | B2: 0.12 | C2: CA-China (2020).txt | D2: 0.12 | E2: ID-Aus (2019).txt | F2: 0.24 | G2: LA-US (2003).txt | H2: 0.02 | I2: 517_Japan Malaysia_2005Cut.txt | J2: 0.12 | K2: 519_Japan Philippines_2006Cut.txt | L2: 0.12 | M2: 396_EFTA Singapore_2002Cut.txt | N2: 0.08 | O2: 632_New Zealand Thailand_2005Cut.txt | P2: 0.11 | Q2: 523_Japan Vietnam_2008Cut.txt | R2: 0.11
C3: CA-ROK (2021).txt | D3: 0.07 | E3: ID-Canada (2025).txt | F3: 0.14 | I3: 599_Malaysia Pakistan_2007Cut.txt | J3: 0.14 | K3: PH-EFTA (2016).txt | L3: 0.04 | M3: 475_Gulf Cooperation Council (GCC) Singapore_2008Cut.txt | N3: 0.11 | O3: 771_Peru Thailand_2005Cut.txt | P3: 0 | Q3: VN-Chile (2011).txt | R3: 0.08
C4: CA-UAE (2023).txt | D4: 0.12 | E4: ID-Chile (2017).txt | F4: 0.06 | I4: 795_Australia Malaysia_2012 cut.txt | J4: 0.19 | K4: PH-Korea (2023).txt | L4: 0.08 | M4: 493_India Singapore_2005Cut.txt | N4: 0.16 | O4: 83_Australia Thailand_2004.txt | P4: 0.09 | Q4: VN-EEU (2015).txt | R4: 0.1
C5: CA-US (2025).txt | D5: 0 | E5: ID-EFTA (2018).txt | F5: 0.09 | I5: 800_Chile Malaysia_2010 cut.txt | J5: 0.05 | M5: 520_Japan Singapore_2002Cut.txt | N5: 0.14 | O5: TH-Chile (2013).txt | P5: 0.11 | Q5: VN-EU + Investment (2019).txt | R5: 0.12
E6: ID-Japan (2007).txt | F6: 0.1 | I6: MY-EFTA (2025).txt | J6: 0.11 | M6: 534_Jordan Singapore_2004Cut.txt | N6: 0.06 | O6: TH-EFTA (2025).txt | P6: 0.1 | Q6: VN-Israel (2023).txt | R6: 0.11
E7: ID-ROK (2020).txt | F7: 0.2 | I7: MY-India (2011).txt | J7: 0.19 | M7: 550_Korea Singapore_2005Cut.txt | N7: 0.13 | O7: TH-India (2003).txt | P7: 0 | Q7: VN-ROK (2015).txt | R7: 0.19
E8: ID-UAE (2022).txt | F8: 0.13 | I8: MY-NZ (2009).txt | J8: 0.19 | M8: 631_New Zealand Singapore_2000Cut.txt | N8: 0.06 | O8: TH-Japan (2007).txt | P8: 0.12 | Q8: VN-UAE (2024).txt | R8: 0.11
I9: MY-Turkey (2022).txt | J9: 0.22 | M9: 641_Panama Singapore_2006Cut.txt | N9: 0.12 | Q9: VN-US (2000).txt | R9: 0.07
I10: MY-UAE (2025).txt | J10: 0.12 | M10: 644_Peru Singapore_2008Cut.txt | N10: 0.13
M11: 658_Singapore US_2003Cut.txt | N11: 0.12
M12: 814_Costa Rica Singapore_2010 cut.txt | N12: 0.13
M13: 82_Australia Singapore_2003Cut.txt | N13: 0.15
M14: 874_EC Singapore_ (cut) + Investment (2018).txt | N14: 0.13
M15: SG-Armenia (2019).txt | N15: 0.11
M16: SG-China (2023).txt | N16: 0.19
M17: SG-Costa Rica (2010).txt | N17: 0.13
M18: SG-Kazakh (2023).txt | N18: 0.11
M19: SG-Mercosur (2023).txt | N19: 0.13
M20: SG-Pacific Alliance (2022).txt | N20: 0.14
M21: SG-TW (2013).txt | N21: 0.13
